2025-06-14 10:39:31,826 INFO [app.py:116] ログシステムを初期化しました (開発環境, レベル: INFO)
2025-06-14 10:39:31,832 INFO [app.py:128] 現在の作業ディレクトリ: /Users/taku/Desktop/projects/server_money
2025-06-14 10:39:31,832 INFO [app.py:129] データベースURI: sqlite:///money_tracker.db
2025-06-14 10:39:31,834 INFO [app.py:599] アプリケーションを開始しています...
2025-06-14 10:39:31,837 INFO [app.py:166] テーブル 'transaction' は既に存在します。
2025-06-14 10:39:31,837 INFO [app.py:601] サーバーを起動します (host=0.0.0.0, port=4000)
2025-06-14 10:39:43,347 INFO [app.py:208] テーブルが存在しないため、作成します...
2025-06-14 10:39:43,347 INFO [app.py:208] テーブルが存在しないため、作成します...
2025-06-14 10:39:43,348 INFO [app.py:211] テーブルを作成しました
2025-06-14 10:39:43,349 INFO [app.py:211] テーブルを作成しました
2025-06-14 10:39:43,354 INFO [app.py:208] テーブルが存在しないため、作成します...
2025-06-14 10:39:43,355 INFO [app.py:211] テーブルを作成しました
2025-06-14 10:39:54,710 INFO [app.py:208] テーブルが存在しないため、作成します...
2025-06-14 10:39:54,712 INFO [app.py:208] テーブルが存在しないため、作成します...
2025-06-14 10:39:54,712 INFO [app.py:211] テーブルを作成しました
2025-06-14 10:39:54,713 INFO [app.py:211] テーブルを作成しました
2025-06-14 10:39:54,716 INFO [app.py:208] テーブルが存在しないため、作成します...
2025-06-14 10:39:54,716 INFO [app.py:211] テーブルを作成しました
2025-06-14 10:39:56,774 INFO [app.py:391] ログファイルダウンロードを開始しています
2025-06-14 10:39:56,775 INFO [app.py:425] ログファイルをダウンロード提供: logs/money_tracker.log
2025-06-14 10:40:23,890 INFO [app.py:208] テーブルが存在しないため、作成します...
2025-06-14 10:40:23,891 INFO [app.py:211] テーブルを作成しました
2025-06-14 10:40:26,021 INFO [app.py:208] テーブルが存在しないため、作成します...
2025-06-14 10:40:26,022 INFO [app.py:211] テーブルを作成しました
2025-06-14 10:40:35,782 INFO [app.py:608] アプリケーションを終了します
2025-07-20 14:42:15,261 INFO [config.py:95] ログシステムを初期化しました (本番環境, レベル: INFO)
2025-07-20 14:42:15,261 INFO [app.py:58] 認証設定を確認しました
2025-07-20 14:42:15,276 INFO [app.py:68] アプリケーションの初期化が完了しました
2025-07-20 14:42:15,276 INFO [app.py:76] アプリケーションを開始しています...
2025-07-20 14:42:15,279 INFO [utils.py:55] テーブル 'transaction' が存在しないので作成します。
2025-07-20 14:42:15,280 INFO [utils.py:57] データベースとテーブルが正常に作成されました。
2025-07-20 14:42:15,280 INFO [app.py:81] サーバーを起動します (host=0.0.0.0, port=4000)
2025-07-20 14:42:32,065 ERROR [app.py:875] Exception on / [GET]
Traceback (most recent call last):
  File "/Users/taku/Desktop/projects/server_money/.venv/lib/python3.12/site-packages/flask/app.py", line 1511, in wsgi_app
    response = self.full_dispatch_request()
               ^^^^^^^^^^^^^^^^^^^^^^^^^^^^
  File "/Users/taku/Desktop/projects/server_money/.venv/lib/python3.12/site-packages/flask/app.py", line 919, in full_dispatch_request
    rv = self.handle_user_exception(e)
         ^^^^^^^^^^^^^^^^^^^^^^^^^^^^^
  File "/Users/taku/Desktop/projects/server_money/.venv/lib/python3.12/site-packages/flask/app.py", line 917, in full_dispatch_request
    rv = self.dispatch_request()
         ^^^^^^^^^^^^^^^^^^^^^^^
  File "/Users/taku/Desktop/projects/server_money/.venv/lib/python3.12/site-packages/flask/app.py", line 902, in dispatch_request
    return self.ensure_sync(self.view_functions[rule.endpoint])(**view_args)  # type: ignore[no-any-return]
           ^^^^^^^^^^^^^^^^^^^^^^^^^^^^^^^^^^^^^^^^^^^^^^^^^^^^^^^^^^^^^^^^^
  File "/Users/taku/Desktop/projects/server_money/auth.py", line 93, in decorated_function
    return redirect(url_for('login_page'))
                    ^^^^^^^^^^^^^^^^^^^^^
  File "/Users/taku/Desktop/projects/server_money/.venv/lib/python3.12/site-packages/flask/helpers.py", line 232, in url_for
    return current_app.url_for(
           ^^^^^^^^^^^^^^^^^^^^
  File "/Users/taku/Desktop/projects/server_money/.venv/lib/python3.12/site-packages/flask/app.py", line 1121, in url_for
    return self.handle_url_build_error(error, endpoint, values)
           ^^^^^^^^^^^^^^^^^^^^^^^^^^^^^^^^^^^^^^^^^^^^^^^^^^^^
  File "/Users/taku/Desktop/projects/server_money/.venv/lib/python3.12/site-packages/flask/app.py", line 1110, in url_for
    rv = url_adapter.build(  # type: ignore[union-attr]
         ^^^^^^^^^^^^^^^^^^^^^^^^^^^^^^^^^^^^^^^^^^^^^^
  File "/Users/taku/Desktop/projects/server_money/.venv/lib/python3.12/site-packages/werkzeug/routing/map.py", line 924, in build
    raise BuildError(endpoint, values, method, self)
werkzeug.routing.exceptions.BuildError: Could not build url for endpoint 'login_page'. Did you mean 'auth.login_page' instead?
2025-07-20 14:43:35,215 INFO [app.py:94] アプリケーションを終了します
2025-07-20 14:43:54,100 INFO [config.py:95] ログシステムを初期化しました (本番環境, レベル: INFO)
2025-07-20 14:43:54,100 INFO [app.py:58] 認証設定を確認しました
2025-07-20 14:43:54,104 INFO [app.py:68] アプリケーションの初期化が完了しました
2025-07-20 14:43:54,104 INFO [app.py:76] アプリケーションを開始しています...
2025-07-20 14:43:54,106 INFO [utils.py:59] テーブル 'transaction' は既に存在します。
2025-07-20 14:43:54,106 INFO [app.py:81] サーバーを起動します (host=0.0.0.0, port=4000)
2025-07-20 14:44:21,235 INFO [auth_routes.py:65] ユーザー 'taku' がログインしました (IP: 127.0.0.1)
2025-07-20 14:44:22,423 INFO [utils.py:80] テーブルが存在しないため、作成します...
2025-07-20 14:44:22,423 INFO [utils.py:80] テーブルが存在しないため、作成します...
2025-07-20 14:44:22,424 INFO [utils.py:83] テーブルを作成しました
2025-07-20 14:44:22,424 INFO [utils.py:83] テーブルを作成しました
2025-07-20 14:44:22,433 INFO [utils.py:80] テーブルが存在しないため、作成します...
2025-07-20 14:44:22,434 INFO [utils.py:83] テーブルを作成しました
2025-07-20 14:44:35,204 INFO [utils.py:80] テーブルが存在しないため、作成します...
2025-07-20 14:44:35,205 INFO [utils.py:83] テーブルを作成しました
2025-07-20 14:44:49,207 INFO [api_routes.py:134] 新しい取引を追加しました: テスト - テスト - 1000円
2025-07-20 14:44:50,214 INFO [utils.py:80] テーブルが存在しないため、作成します...
2025-07-20 14:44:50,215 INFO [utils.py:83] テーブルを作成しました
2025-07-20 14:44:50,220 INFO [utils.py:80] テーブルが存在しないため、作成します...
2025-07-20 14:44:50,221 INFO [utils.py:83] テーブルを作成しました
2025-07-20 14:44:51,450 INFO [utils.py:80] テーブルが存在しないため、作成します...
2025-07-20 14:44:51,451 INFO [utils.py:83] テーブルを作成しました
2025-07-20 14:45:01,813 INFO [api_routes.py:134] 新しい取引を追加しました: テスト - テスト - 5000円
2025-07-20 14:45:02,773 INFO [utils.py:80] テーブルが存在しないため、作成します...
2025-07-20 14:45:02,775 INFO [utils.py:83] テーブルを作成しました
2025-07-20 14:45:02,783 INFO [utils.py:80] テーブルが存在しないため、作成します...
2025-07-20 14:45:02,784 INFO [utils.py:83] テーブルを作成しました
